[2023-03-17T18:33:06.686+0000] {taskinstance.py:1083} INFO - Dependencies all met for <TaskInstance: get_file_from_endpoint.download_file manual__2023-03-17T18:32:46.414285+00:00 [queued]>
[2023-03-17T18:33:06.697+0000] {taskinstance.py:1083} INFO - Dependencies all met for <TaskInstance: get_file_from_endpoint.download_file manual__2023-03-17T18:32:46.414285+00:00 [queued]>
[2023-03-17T18:33:06.697+0000] {taskinstance.py:1279} INFO - 
--------------------------------------------------------------------------------
[2023-03-17T18:33:06.698+0000] {taskinstance.py:1280} INFO - Starting attempt 1 of 1
[2023-03-17T18:33:06.698+0000] {taskinstance.py:1281} INFO - 
--------------------------------------------------------------------------------
[2023-03-17T18:33:06.712+0000] {taskinstance.py:1300} INFO - Executing <Task(PythonOperator): download_file> on 2023-03-17 18:32:46.414285+00:00
[2023-03-17T18:33:06.716+0000] {standard_task_runner.py:55} INFO - Started process 5594 to run task
[2023-03-17T18:33:06.724+0000] {standard_task_runner.py:82} INFO - Running: ['***', 'tasks', 'run', 'get_file_from_endpoint', 'download_file', 'manual__2023-03-17T18:32:46.414285+00:00', '--job-id', '241', '--raw', '--subdir', 'DAGS_FOLDER/api.py', '--cfg-path', '/tmp/tmp8pa989ll']
[2023-03-17T18:33:06.726+0000] {standard_task_runner.py:83} INFO - Job 241: Subtask download_file
[2023-03-17T18:33:06.822+0000] {task_command.py:388} INFO - Running <TaskInstance: get_file_from_endpoint.download_file manual__2023-03-17T18:32:46.414285+00:00 [running]> on host diploma-vm.europe-west1-b.c.diploma-380314.internal
[2023-03-17T18:33:06.910+0000] {taskinstance.py:1507} INFO - Exporting the following env vars:
AIRFLOW_CTX_DAG_OWNER=***
AIRFLOW_CTX_DAG_ID=get_file_from_endpoint
AIRFLOW_CTX_TASK_ID=download_file
AIRFLOW_CTX_EXECUTION_DATE=2023-03-17T18:32:46.414285+00:00
AIRFLOW_CTX_TRY_NUMBER=1
AIRFLOW_CTX_DAG_RUN_ID=manual__2023-03-17T18:32:46.414285+00:00
[2023-03-17T18:33:06.912+0000] {taskinstance.py:1768} ERROR - Task failed with exception
Traceback (most recent call last):
  File "/home/melicharovykrecek/venv/lib/python3.9/site-packages/airflow/operators/python.py", line 175, in execute
    return_value = self.execute_callable()
  File "/home/melicharovykrecek/venv/lib/python3.9/site-packages/airflow/operators/python.py", line 192, in execute_callable
    return self.python_callable(*self.op_args, **self.op_kwargs)
  File "/home/melicharovykrecek/diploma/dags/api.py", line 26, in download_file
    print(test)
NameError: name 'test' is not defined
[2023-03-17T18:33:06.927+0000] {taskinstance.py:1318} INFO - Marking task as FAILED. dag_id=get_file_from_endpoint, task_id=download_file, execution_date=20230317T183246, start_date=20230317T183306, end_date=20230317T183306
[2023-03-17T18:33:06.942+0000] {standard_task_runner.py:100} ERROR - Failed to execute job 241 for task download_file (name 'test' is not defined; 5594)
[2023-03-17T18:33:06.973+0000] {local_task_job.py:208} INFO - Task exited with return code 1
[2023-03-17T18:33:07.003+0000] {taskinstance.py:2578} INFO - 0 downstream tasks scheduled from follow-on schedule check
