[2023-03-12T12:23:22.011+0000] {taskinstance.py:1083} INFO - Dependencies all met for <TaskInstance: get_file_from_endpoint.check_endpoint manual__2023-03-12T12:23:21.232107+00:00 [queued]>
[2023-03-12T12:23:22.025+0000] {taskinstance.py:1083} INFO - Dependencies all met for <TaskInstance: get_file_from_endpoint.check_endpoint manual__2023-03-12T12:23:21.232107+00:00 [queued]>
[2023-03-12T12:23:22.025+0000] {taskinstance.py:1279} INFO - 
--------------------------------------------------------------------------------
[2023-03-12T12:23:22.025+0000] {taskinstance.py:1280} INFO - Starting attempt 1 of 1
[2023-03-12T12:23:22.025+0000] {taskinstance.py:1281} INFO - 
--------------------------------------------------------------------------------
[2023-03-12T12:23:22.041+0000] {taskinstance.py:1300} INFO - Executing <Task(PythonOperator): check_endpoint> on 2023-03-12 12:23:21.232107+00:00
[2023-03-12T12:23:22.046+0000] {standard_task_runner.py:55} INFO - Started process 12598 to run task
[2023-03-12T12:23:22.050+0000] {standard_task_runner.py:82} INFO - Running: ['***', 'tasks', 'run', 'get_file_from_endpoint', 'check_endpoint', 'manual__2023-03-12T12:23:21.232107+00:00', '--job-id', '17', '--raw', '--subdir', 'DAGS_FOLDER/api.py', '--cfg-path', '/tmp/tmpax52dzal']
[2023-03-12T12:23:22.053+0000] {standard_task_runner.py:83} INFO - Job 17: Subtask check_endpoint
[2023-03-12T12:23:22.148+0000] {task_command.py:388} INFO - Running <TaskInstance: get_file_from_endpoint.check_endpoint manual__2023-03-12T12:23:21.232107+00:00 [running]> on host diploma-vm.europe-west1-b.c.diploma-380314.internal
[2023-03-12T12:23:22.235+0000] {taskinstance.py:1507} INFO - Exporting the following env vars:
AIRFLOW_CTX_DAG_OWNER=***
AIRFLOW_CTX_DAG_ID=get_file_from_endpoint
AIRFLOW_CTX_TASK_ID=check_endpoint
AIRFLOW_CTX_EXECUTION_DATE=2023-03-12T12:23:21.232107+00:00
AIRFLOW_CTX_TRY_NUMBER=1
AIRFLOW_CTX_DAG_RUN_ID=manual__2023-03-12T12:23:21.232107+00:00
[2023-03-12T12:26:22.343+0000] {taskinstance.py:1768} ERROR - Task failed with exception
Traceback (most recent call last):
  File "/home/melicharovykrecek/venv/lib/python3.9/site-packages/airflow/operators/python.py", line 175, in execute
    return_value = self.execute_callable()
  File "/home/melicharovykrecek/venv/lib/python3.9/site-packages/airflow/operators/python.py", line 192, in execute_callable
    return self.python_callable(*self.op_args, **self.op_kwargs)
  File "/home/melicharovykrecek/diploma/dags/api.py", line 22, in check_endpoint
    raise ValueError('Endpoint not available')
ValueError: Endpoint not available
[2023-03-12T12:26:22.359+0000] {taskinstance.py:1318} INFO - Marking task as FAILED. dag_id=get_file_from_endpoint, task_id=check_endpoint, execution_date=20230312T122321, start_date=20230312T122322, end_date=20230312T122622
[2023-03-12T12:26:22.374+0000] {standard_task_runner.py:100} ERROR - Failed to execute job 17 for task check_endpoint (Endpoint not available; 12598)
[2023-03-12T12:26:22.386+0000] {local_task_job.py:208} INFO - Task exited with return code 1
[2023-03-12T12:26:22.419+0000] {taskinstance.py:2578} INFO - 0 downstream tasks scheduled from follow-on schedule check
